Workbook
Name Slicer_device_type: #N/A
Name Slicer_device_type1: #N/A

Sheet pivot_table
K2: ARPU - Average Revenue Per User
K3: ARPPU - Average Revenue Per Paying User
K4: Payer Conversion Rate - Частка користувачів, які здійснили успішний платіж
A12: device_type | B12: mobile
A14: country_code | B14: Count of user_id | C14: Sum of is_payer | D14: total_paid | E14: total_refunded | F14: total_net_revenue_usd | G14: PCR | H14: ARPU | I14: ARPPU
A15: UA | B15: 24 | C15: 6 | D15: 58.92 | E15: 0 | F15: 58.92 | G15: =IFERROR(C15/B15,0) -> 0.25 | H15: =IFERROR(F15/B15,0) -> 2.455 | I15: =IFERROR(F15/C15,0) -> 9.82
A16: GB | B16: 33 | C16: 7 | D16: 115.9 | E16: 39.98 | F16: 75.92 | G16: =IFERROR(C16/B16,0) -> 0.21212121 | H16: =IFERROR(F16/B16,0) -> 2.3006061 | I16: =IFERROR(F16/C16,0) -> 10.845714
A17: BR | B17: 23 | C17: 6 | D17: 84.93 | E17: 0 | F17: 84.93 | G17: =IFERROR(C17/B17,0) -> 0.26086957 | H17: =IFERROR(F17/B17,0) -> 3.6926087 | I17: =IFERROR(F17/C17,0) -> 14.155
A18: CA | B18: 29 | C18: 9 | D18: 120.9 | E18: 9.99 | F18: 110.91 | G18: =IFERROR(C18/B18,0) -> 0.31034483 | H18: =IFERROR(F18/B18,0) -> 3.8244828 | I18: =IFERROR(F18/C18,0) -> 12.323333
A19: DE | B19: 27 | C19: 8 | D19: 119.89 | E19: 0 | F19: 119.89 | G19: =IFERROR(C19/B19,0) -> 0.2962963 | H19: =IFERROR(F19/B19,0) -> 4.4403704 | I19: =IFERROR(F19/C19,0) -> 14.98625
A20: US | B20: 38 | C20: 13 | D20: 165.86 | E20: 19.99 | F20: 145.87 | G20: =IFERROR(C20/B20,0) -> 0.34210526 | H20: =IFERROR(F20/B20,0) -> 3.8386842 | I20: =IFERROR(F20/C20,0) -> 11.220769
A21: Grand Total | B21: 174 | C21: 49 | D21: 666.4 | E21: 69.96 | F21: 596.44 | G21: =IFERROR(C21/B21,0) -> 0.2816092 | H21: =IFERROR(F21/B21,0) -> 3.4278161 | I21: =IFERROR(F21/C21,0) -> 12.172245
A34: country_code | B34: Total_net_revenue_usd
A35: BR | B35: 133.88
A36: CA | B36: 99.92
A37: DE | B37: 71.94
A38: GB | B38: 9.99
A39: UA | B39: 121.91
A40: US | B40: 104.89
A41: Grand Total | B41: 542.53
A59: device_type | B59: Total_net_revenue_usd
A60: desktop | B60: 542.53
A61: mobile | B61: 596.44
A62: tablet | B62: 578.54
A63: Grand Total | B63: 1717.51
A73: status | B73: succeeded
A75: month | B75: Total_revenue
A76: 2026-01 | B76: 69.96
A77: 2026-02 | B77: 84.91
A78: 2026-03 | B78: 295.75
A79: 2026-04 | B79: 349.7
A80: 2026-05 | B80: 540.53
A81: 2026-06 | B81: 586.52
A82: Grand Total | B82: 1927.37
A90: Month | B90: Total_refunded
A91: 2026-01 | B91: 39.98
A92: 2026-02 | B92: 9.99
A93: 2026-03 | B93: 39.98
A94: 2026-04 | B94: 34.97
A95: 2026-05 | B95: 49.97
...

Sheet users
A1: user_id | B1: registered_at | C1: country_code | D1: device_type | E1: campaign_id | F1: successful_payments_count | G1: paid_usd | H1: refunded_usd | I1: net_revenue_usd | J1: is_payer
A2: 1 | B2: 46141.401 | C2: BR | D2: desktop | E2: 6 | F2: =COUNTIFS(payments!$B$2:$B$203,A2,payments!$F$2:$F$203,"succeeded") -> 1 | G2: =SUMIFS(payments!$G$2:$G$203,payments!$F$2:$F$203,"succeeded",payments!$B$2:$B$203,A2) -> 9.99 | H2: =SUMIF(refunds!$G$2:$G$15,A2,refunds!$D$2:$D$15) -> 0 | I2: =users[[#This Row],[paid_usd]]-users[[#This Row],[refunded_usd]] -> 9.99 | J2: =IF(users[[#This Row],[successful_payments_count]]>0,1,0) -> 1
A3: 2 | B3: 46144.255 | C3: US | D3: tablet | E3: 7 | F3: =COUNTIFS(payments!$B$2:$B$203,A3,payments!$F$2:$F$203,"succeeded") -> 0 | G3: =SUMIFS(payments!$G$2:$G$203,payments!$F$2:$F$203,"succeeded",payments!$B$2:$B$203,A3) -> 0 | H3: =SUMIF(refunds!$G$2:$G$15,A3,refunds!$D$2:$D$15) -> 0 | I3: =users[[#This Row],[paid_usd]]-users[[#This Row],[refunded_usd]] -> 0 | J3: =IF(users[[#This Row],[successful_payments_count]]>0,1,0) -> 0
A4: 3 | B4: 46075.402 | C4: CA | D4: mobile | E4: 5 | F4: =COUNTIFS(payments!$B$2:$B$203,A4,payments!$F$2:$F$203,"succeeded") -> 0 | G4: =SUMIFS(payments!$G$2:$G$203,payments!$F$2:$F$203,"succeeded",payments!$B$2:$B$203,A4) -> 0 | H4: =SUMIF(refunds!$G$2:$G$15,A4,refunds!$D$2:$D$15) -> 0 | I4: =users[[#This Row],[paid_usd]]-users[[#This Row],[refunded_usd]] -> 0 | J4: =IF(users[[#This Row],[successful_payments_count]]>0,1,0) -> 0
A5: 4 | B5: 46156.777 | C5: DE | D5: mobile | E5: 6 | F5: =COUNTIFS(payments!$B$2:$B$203,A5,payments!$F$2:$F$203,"succeeded") -> 0 | G5: =SUMIFS(payments!$G$2:$G$203,payments!$F$2:$F$203,"succeeded",payments!$B$2:$B$203,A5) -> 0 | H5: =SUMIF(refunds!$G$2:$G$15,A5,refunds!$D$2:$D$15) -> 0 | I5: =users[[#This Row],[paid_usd]]-users[[#This Row],[refunded_usd]] -> 0 | J5: =IF(users[[#This Row],[successful_payments_count]]>0,1,0) -> 0
A6: 5 | B6: 46178.485 | C6: CA | D6: mobile | E6: 3 | F6: =COUNTIFS(payments!$B$2:$B$203,A6,payments!$F$2:$F$203,"succeeded") -> 1 | G6: =SUMIFS(payments!$G$2:$G$203,payments!$F$2:$F$203,"succeeded",payments!$B$2:$B$203,A6) -> 9.99 | H6: =SUMIF(refunds!$G$2:$G$15,A6,refunds!$D$2:$D$15) -> 0 | I6: =users[[#This Row],[paid_usd]]-users[[#This Row],[refunded_usd]] -> 9.99 | J6: =IF(users[[#This Row],[successful_payments_count]]>0,1,0) -> 1
A7: 6 | B7: 46192.189 | C7: GB | D7: tablet | E7: 1 | F7: =COUNTIFS(payments!$B$2:$B$203,A7,payments!$F$2:$F$203,"succeeded") -> 0 | G7: =SUMIFS(payments!$G$2:$G$203,payments!$F$2:$F$203,"succeeded",payments!$B$2:$B$203,A7) -> 0 | H7: =SUMIF(refunds!$G$2:$G$15,A7,refunds!$D$2:$D$15) -> 0 | I7: =users[[#This Row],[paid_usd]]-users[[#This Row],[refunded_usd]] -> 0 | J7: =IF(users[[#This Row],[successful_payments_count]]>0,1,0) -> 0
A8: 7 | B8: 46119.771 | C8: US | D8: tablet | F8: =COUNTIFS(payments!$B$2:$B$203,A8,payments!$F$2:$F$203,"succeeded") -> 0 | G8: =SUMIFS(payments!$G$2:$G$203,payments!$F$2:$F$203,"succeeded",payments!$B$2:$B$203,A8) -> 0 | H8: =SUMIF(refunds!$G$2:$G$15,A8,refunds!$D$2:$D$15) -> 0 | I8: =users[[#This Row],[paid_usd]]-users[[#This Row],[refunded_usd]] -> 0 | J8: =IF(users[[#This Row],[successful_payments_count]]>0,1,0) -> 0
A9: 8 | B9: 46033.854 | C9: CA | D9: desktop | E9: 3 | F9: =COUNTIFS(payments!$B$2:$B$203,A9,payments!$F$2:$F$203,"succeeded") -> 1 | G9: =SUMIFS(payments!$G$2:$G$203,payments!$F$2:$F$203,"succeeded",payments!$B$2:$B$203,A9) -> 4.99 | H9: =SUMIF(refunds!$G$2:$G$15,A9,refunds!$D$2:$D$15) -> 0 | I9: =users[[#This Row],[paid_usd]]-users[[#This Row],[refunded_usd]] -> 4.99 | J9: =IF(users[[#This Row],[successful_payments_count]]>0,1,0) -> 1
A10: 9 | B10: 46142.296 | C10: BR | D10: tablet | E10: 3 | F10: =COUNTIFS(payments!$B$2:$B$203,A10,payments!$F$2:$F$203,"succeeded") -> 0 | G10: =SUMIFS(payments!$G$2:$G$203,payments!$F$2:$F$203,"succeeded",payments!$B$2:$B$203,A10) -> 0 | H10: =SUMIF(refunds!$G$2:$G$15,A10,refunds!$D$2:$D$15) -> 0 | I10: =users[[#This Row],[paid_usd]]-users[[#This Row],[refunded_usd]] -> 0 | J10: =IF(users[[#This Row],[successful_payments_count]]>0,1,0) -> 0
A11: 10 | B11: 46098.247 | C11: BR | D11: desktop | E11: 7 | F11: =COUNTIFS(payments!$B$2:$B$203,A11,payments!$F$2:$F$203,"succeeded") -> 0 | G11: =SUMIFS(payments!$G$2:$G$203,payments!$F$2:$F$203,"succeeded",payments!$B$2:$B$203,A11) -> 0 | H11: =SUMIF(refunds!$G$2:$G$15,A11,refunds!$D$2:$D$15) -> 0 | I11: =users[[#This Row],[paid_usd]]-users[[#This Row],[refunded_usd]] -> 0 | J11: =IF(users[[#This Row],[successful_payments_count]]>0,1,0) -> 0
A12: 11 | B12: 46053.589 | C12: UA | D12: mobile | E12: 2 | F12: =COUNTIFS(payments!$B$2:$B$203,A12,payments!$F$2:$F$203,"succeeded") -> 0 | G12: =SUMIFS(payments!$G$2:$G$203,payments!$F$2:$F$203,"succeeded",payments!$B$2:$B$203,A12) -> 0 | H12: =SUMIF(refunds!$G$2:$G$15,A12,refunds!$D$2:$D$15) -> 0 | I12: =users[[#This Row],[paid_usd]]-users[[#This Row],[refunded_usd]] -> 0 | J12: =IF(users[[#This Row],[successful_payments_count]]>0,1,0) -> 0
A13: 12 | B13: 46101.561 | C13: DE | D13: mobile | F13: =COUNTIFS(payments!$B$2:$B$203,A13,payments!$F$2:$F$203,"succeeded") -> 0 | G13: =SUMIFS(payments!$G$2:$G$203,payments!$F$2:$F$203,"succeeded",payments!$B$2:$B$203,A13) -> 0 | H13: =SUMIF(refunds!$G$2:$G$15,A13,refunds!$D$2:$D$15) -> 0 | I13: =users[[#This Row],[paid_usd]]-users[[#This Row],[refunded_usd]] -> 0 | J13: =IF(users[[#This Row],[successful_payments_count]]>0,1,0) -> 0
A14: 13 | B14: 46092.445 | C14: UA | D14: tablet | E14: 2 | F14: =COUNTIFS(payments!$B$2:$B$203,A14,payments!$F$2:$F$203,"succeeded") -> 1 | G14: =SUMIFS(payments!$G$2:$G$203,payments!$F$2:$F$203,"succeeded",payments!$B$2:$B$203,A14) -> 7.99 | H14: =SUMIF(refunds!$G$2:$G$15,A14,refunds!$D$2:$D$15) -> 0 | I14: =users[[#This Row],[paid_usd]]-users[[#This Row],[refunded_usd]] -> 7.99 | J14: =IF(users[[#This Row],[successful_payments_count]]>0,1,0) -> 1
A15: 14 | B15: 46174.386 | C15: BR | D15: tablet | E15: 2 | F15: =COUNTIFS(payments!$B$2:$B$203,A15,payments!$F$2:$F$203,"succeeded") -> 0 | G15: =SUMIFS(payments!$G$2:$G$203,payments!$F$2:$F$203,"succeeded",payments!$B$2:$B$203,A15) -> 0 | H15: =SUMIF(refunds!$G$2:$G$15,A15,refunds!$D$2:$D$15) -> 0 | I15: =users[[#This Row],[paid_usd]]-users[[#This Row],[refunded_usd]] -> 0 | J15: =IF(users[[#This Row],[successful_payments_count]]>0,1,0) -> 0
A16: 15 | B16: 46120.76 | C16: CA | D16: mobile | F16: =COUNTIFS(payments!$B$2:$B$203,A16,payments!$F$2:$F$203,"succeeded") -> 0 | G16: =SUMIFS(payments!$G$2:$G$203,payments!$F$2:$F$203,"succeeded",payments!$B$2:$B$203,A16) -> 0 | H16: =SUMIF(refunds!$G$2:$G$15,A16,refunds!$D$2:$D$15) -> 0 | I16: =users[[#This Row],[paid_usd]]-users[[#This Row],[refunded_usd]] -> 0 | J16: =IF(users[[#This Row],[successful_payments_count]]>0,1,0) -> 0
A17: 16 | B17: 46125.781 | C17: GB | D17: tablet | E17: 5 | F17: =COUNTIFS(payments!$B$2:$B$203,A17,payments!$F$2:$F$203,"succeeded") -> 0 | G17: =SUMIFS(payments!$G$2:$G$203,payments!$F$2:$F$203,"succeeded",payments!$B$2:$B$203,A17) -> 0 | H17: =SUMIF(refunds!$G$2:$G$15,A17,refunds!$D$2:$D$15) -> 0 | I17: =users[[#This Row],[paid_usd]]-users[[#This Row],[refunded_usd]] -> 0 | J17: =IF(users[[#This Row],[successful_payments_count]]>0,1,0) -> 0
A18: 17 | B18: 46106.469 | C18: BR | D18: desktop | E18: 7 | F18: =COUNTIFS(payments!$B$2:$B$203,A18,payments!$F$2:$F$203,"succeeded") -> 0 | G18: =SUMIFS(payments!$G$2:$G$203,payments!$F$2:$F$203,"succeeded",payments!$B$2:$B$203,A18) -> 0 | H18: =SUMIF(refunds!$G$2:$G$15,A18,refunds!$D$2:$D$15) -> 0 | I18: =users[[#This Row],[paid_usd]]-users[[#This Row],[refunded_usd]] -> 0 | J18: =IF(users[[#This Row],[successful_payments_count]]>0,1,0) -> 0
A19: 18 | B19: 46169.444 | C19: UA | D19: desktop | E19: 3 | F19: =COUNTIFS(payments!$B$2:$B$203,A19,payments!$F$2:$F$203,"succeeded") -> 0 | G19: =SUMIFS(payments!$G$2:$G$203,payments!$F$2:$F$203,"succeeded",payments!$B$2:$B$203,A19) -> 0 | H19: =SUMIF(refunds!$G$2:$G$15,A19,refunds!$D$2:$D$15) -> 0 | I19: =users[[#This Row],[paid_usd]]-users[[#This Row],[refunded_usd]] -> 0 | J19: =IF(users[[#This Row],[successful_payments_count]]>0,1,0) -> 0
A20: 19 | B20: 46025.986 | C20: DE | D20: mobile | E20: 7 | F20: =COUNTIFS(payments!$B$2:$B$203,A20,payments!$F$2:$F$203,"succeeded") -> 0 | G20: =SUMIFS(payments!$G$2:$G$203,payments!$F$2:$F$203,"succeeded",payments!$B$2:$B$203,A20) -> 0 | H20: =SUMIF(refunds!$G$2:$G$15,A20,refunds!$D$2:$D$15) -> 0 | I20: =users[[#This Row],[paid_usd]]-users[[#This Row],[refunded_usd]] -> 0 | J20: =IF(users[[#This Row],[successful_payments_count]]>0,1,0) -> 0
A21: 20 | B21: 46050.021 | C21: US | D21: mobile | E21: 5 | F21: =COUNTIFS(payments!$B$2:$B$203,A21,payments!$F$2:$F$203,"succeeded") -> 0 | G21: =SUMIFS(payments!$G$2:$G$203,payments!$F$2:$F$203,"succeeded",payments!$B$2:$B$203,A21) -> 0 | H21: =SUMIF(refunds!$G$2:$G$15,A21,refunds!$D$2:$D$15) -> 0 | I21: =users[[#This Row],[paid_usd]]-users[[#This Row],[refunded_usd]] -> 0 | J21: =IF(users[[#This Row],[successful_payments_count]]>0,1,0) -> 0
A22: 21 | B22: 46180 | C22: GB | D22: desktop | E22: 6 | F22: =COUNTIFS(payments!$B$2:$B$203,A22,payments!$F$2:$F$203,"succeeded") -> 0 | G22: =SUMIFS(payments!$G$2:$G$203,payments!$F$2:$F$203,"succeeded",payments!$B$2:$B$203,A22) -> 0 | H22: =SUMIF(refunds!$G$2:$G$15,A22,refunds!$D$2:$D$15) -> 0 | I22: =users[[#This Row],[paid_usd]]-users[[#This Row],[refunded_usd]] -> 0 | J22: =IF(users[[#This Row],[successful_payments_count]]>0,1,0) -> 0
A23: 22 | B23: 46059.253 | C23: UA | D23: tablet | E23: 4 | F23: =COUNTIFS(payments!$B$2:$B$203,A23,payments!$F$2:$F$203,"succeeded") -> 0 | G23: =SUMIFS(payments!$G$2:$G$203,payments!$F$2:$F$203,"succeeded",payments!$B$2:$B$203,A23) -> 0 | H23: =SUMIF(refunds!$G$2:$G$15,A23,refunds!$D$2:$D$15) -> 0 | I23: =users[[#This Row],[paid_usd]]-users[[#This Row],[refunded_usd]] -> 0 | J23: =IF(users[[#This Row],[successful_payments_count]]>0,1,0) -> 0
A24: 23 | B24: 46116.1 | C24: US | D24: mobile | E24: 1 | F24: =COUNTIFS(payments!$B$2:$B$203,A24,payments!$F$2:$F$203,"succeeded") -> 0 | G24: =SUMIFS(payments!$G$2:$G$203,payments!$F$2:$F$203,"succeeded",payments!$B$2:$B$203,A24) -> 0 | H24: =SUMIF(refunds!$G$2:$G$15,A24,refunds!$D$2:$D$15) -> 0 | I24: =users[[#This Row],[paid_usd]]-users[[#This Row],[refunded_usd]] -> 0 | J24: =IF(users[[#This Row],[successful_payments_count]]>0,1,0) -> 0
A25: 24 | B25: 46045.702 | C25: DE | D25: mobile | E25: 6 | F25: =COUNTIFS(payments!$B$2:$B$203,A25,payments!$F$2:$F$203,"succeeded") -> 0 | G25: =SUMIFS(payments!$G$2:$G$203,payments!$F$2:$F$203,"succeeded",payments!$B$2:$B$203,A25) -> 0 | H25: =SUMIF(refunds!$G$2:$G$15,A25,refunds!$D$2:$D$15) -> 0 | I25: =users[[#This Row],[paid_usd]]-users[[#This Row],[refunded_usd]] -> 0 | J25: =IF(users[[#This Row],[successful_payments_count]]>0,1,0) -> 0
A26: 25 | B26: 46035.442 | C26: GB | D26: tablet | E26: 2 | F26: =COUNTIFS(payments!$B$2:$B$203,A26,payments!$F$2:$F$203,"succeeded") -> 0 | G26: =SUMIFS(payments!$G$2:$G$203,payments!$F$2:$F$203,"succeeded",payments!$B$2:$B$203,A26) -> 0 | H26: =SUMIF(refunds!$G$2:$G$15,A26,refunds!$D$2:$D$15) -> 0 | I26: =users[[#This Row],[paid_usd]]-users[[#This Row],[refunded_usd]] -> 0 | J26: =IF(users[[#This Row],[successful_payments_count]]>0,1,0) -> 0
A27: 26 | B27: 46132.104 | C27: CA | D27: tablet | E27: 5 | F27: =COUNTIFS(payments!$B$2:$B$203,A27,payments!$F$2:$F$203,"succeeded") -> 0 | G27: =SUMIFS(payments!$G$2:$G$203,payments!$F$2:$F$203,"succeeded",payments!$B$2:$B$203,A27) -> 0 | H27: =SUMIF(refunds!$G$2:$G$15,A27,refunds!$D$2:$D$15) -> 0 | I27: =users[[#This Row],[paid_usd]]-users[[#This Row],[refunded_usd]] -> 0 | J27: =IF(users[[#This Row],[successful_payments_count]]>0,1,0) -> 0
A28: 27 | B28: 46090.001 | C28: DE | D28: desktop | E28: 7 | F28: =COUNTIFS(payments!$B$2:$B$203,A28,payments!$F$2:$F$203,"succeeded") -> 0 | G28: =SUMIFS(payments!$G$2:$G$203,payments!$F$2:$F$203,"succeeded",payments!$B$2:$B$203,A28) -> 0 | H28: =SUMIF(refunds!$G$2:$G$15,A28,refunds!$D$2:$D$15) -> 0 | I28: =users[[#This Row],[paid_usd]]-users[[#This Row],[refunded_usd]] -> 0 | J28: =IF(users[[#This Row],[successful_payments_count]]>0,1,0) -> 0
... A31: 30 | B31: 46093.777 | C31: GB | D31: tablet | E31: 3 | F31: =COUNTIFS(payments!$B$2:$B$203,A31,payments!$F$2:$F$203,"succeeded") -> 0 | G31: =SUMIFS(payments!$G$2:$G$203,payments!$F$2:$F$203,"succeeded",payments!$B$2:$B$203,A31) -> 0 | H31: =SUMIF(refunds!$G$2:$G$15,A31,refunds!$D$2:$D$15) -> 0 | I31: =users[[#This Row],[paid_usd]]-users[[#This Row],[refunded_usd]] -> 0 | J31: =IF(users[[#This Row],[successful_payments_count]]>0,1,0) -> 0
A32: 31 | B32: 46042.739 | C32: DE | D32: desktop | F32: =COUNTIFS(payments!$B$2:$B$203,A32,payments!$F$2:$F$203,"succeeded") -> 0 | G32: =SUMIFS(payments!$G$2:$G$203,payments!$F$2:$F$203,"succeeded",payments!$B$2:$B$203,A32) -> 0 | H32: =SUMIF(refunds!$G$2:$G$15,A32,refunds!$D$2:$D$15) -> 0 | I32: =users[[#This Row],[paid_usd]]-users[[#This Row],[refunded_usd]] -> 0 | J32: =IF(users[[#This Row],[successful_payments_count]]>0,1,0) -> 0
A33: 32 | B33: 46124.451 | C33: BR | D33: desktop | E33: 3 | F33: =COUNTIFS(payments!$B$2:$B$203,A33,payments!$F$2:$F$203,"succeeded") -> 0 | G33: =SUMIFS(payments!$G$2:$G$203,payments!$F$2:$F$203,"succeeded",payments!$B$2:$B$203,A33) -> 0 | H33: =SUMIF(refunds!$G$2:$G$15,A33,refunds!$D$2:$D$15) -> 0 | I33: =users[[#This Row],[paid_usd]]-users[[#This Row],[refunded_usd]] -> 0 | J33: =IF(users[[#This Row],[successful_payments_count]]>0,1,0) -> 0
A34: 33 | B34: 46176.961 | C34: DE | D34: tablet | F34: =COUNTIFS(payments!$B$2:$B$203,A34,payments!$F$2:$F$203,"succeeded") -> 0 | G34: =SUMIFS(payments!$G$2:$G$203,payments!$F$2:$F$203,"succeeded",payments!$B$2:$B$203,A34) -> 0 | H34: =SUMIF(refunds!$G$2:$G$15,A34,refunds!$D$2:$D$15) -> 0 | I34: =users[[#This Row],[paid_usd]]-users[[#This Row],[refunded_usd]] -> 0 | J34: =IF(users[[#This Row],[successful_payments_count]]>0,1,0) -> 0
A35: 34 | B35: 46143.075 | C35: CA | D35: mobile | E35: 6 | F35: =COUNTIFS(payments!$B$2:$B$203,A35,payments!$F$2:$F$203,"succeeded") -> 0 | G35: =SUMIFS(payments!$G$2:$G$203,payments!$F$2:$F$203,"succeeded",payments!$B$2:$B$203,A35) -> 0 | H35: =SUMIF(refunds!$G$2:$G$15,A35,refunds!$D$2:$D$15) -> 0 | I35: =users[[#This Row],[paid_usd]]-users[[#This Row],[refunded_usd]] -> 0 | J35: =IF(users[[#This Row],[successful_payments_count]]>0,1,0) -> 0
A36: 35 | B36: 46055.673 | C36: DE | D36: desktop | E36: 6 | F36: =COUNTIFS(payments!$B$2:$B$203,A36,payments!$F$2:$F$203,"succeeded") -> 0 | G36: =SUMIFS(payments!$G$2:$G$203,payments!$F$2:$F$203,"succeeded",payments!$B$2:$B$203,A36) -> 0 | H36: =SUMIF(refunds!$G$2:$G$15,A36,refunds!$D$2:$D$15) -> 0 | I36: =users[[#This Row],[paid_usd]]-users[[#This Row],[refunded_usd]] -> 0 | J36: =IF(users[[#This Row],[successful_payments_count]]>0,1,0) -> 0
A37: 36 | B37: 46146.992 | C37: US | D37: mobile | E37: 1 | F37: =COUNTIFS(payments!$B$2:$B$203,A37,payments!$F$2:$F$203,"succeeded") -> 1 | G37: =SUMIFS(payments!$G$2:$G$203,payments!$F$2:$F$203,"succeeded",payments!$B$2:$B$203,A37) -> 7.99 | H37: =SUMIF(refunds!$G$2:$G$15,A37,refunds!$D$2:$D$15) -> 0 | I37: =users[[#This Row],[paid_usd]]-users[[#This Row],[refunded_usd]] -> 7.99 | J37: =IF(users[[#This Row],[successful_payments_count]]>0,1,0) -> 1
A38: 37 | B38: 46180.447 | C38: BR | D38: tablet | E38: 6 | F38: =COUNTIFS(payments!$B$2:$B$203,A38,payments!$F$2:$F$203,"succeeded") -> 0 | G38: =SUMIFS(payments!$G$2:$G$203,payments!$F$2:$F$203,"succeeded",payments!$B$2:$B$203,A38) -> 0 | H38: =SUMIF(refunds!$G$2:$G$15,A38,refunds!$D$2:$D$15) -> 0 | I38: =users[[#This Row],[paid_usd]]-users[[#This Row],[refunded_usd]] -> 0 | J38: =IF(users[[#This Row],[successful_payments_count]]>0,1,0) -> 0
A39: 38 | B39: 46140.211 | C39: DE | D39: tablet | E39: 3 | F39: =COUNTIFS(payments!$B$2:$B$203,A39,payments!$F$2:$F$203,"succeeded") -> 0 | G39: =SUMIFS(payments!$G$2:$G$203,payments!$F$2:$F$203,"succeeded",payments!$B$2:$B$203,A39) -> 0 | H39: =SUMIF(refunds!$G$2:$G$15,A39,refunds!$D$2:$D$15) -> 0 | I39: =users[[#This Row],[paid_usd]]-users[[#This Row],[refunded_usd]] -> 0 | J39: =IF(users[[#This Row],[successful_payments_count]]>0,1,0) -> 0
A40: 39 | B40: 46067.437 | C40: US | D40: mobile | E40: 6 | F40: =COUNTIFS(payments!$B$2:$B$203,A40,payments!$F$2:$F$203,"succeeded") -> 0 | G40: =SUMIFS(payments!$G$2:$G$203,payments!$F$2:$F$203,"succeeded",payments!$B$2:$B$203,A40) -> 0 | H40: =SUMIF(refunds!$G$2:$G$15,A40,refunds!$D$2:$D$15) -> 0 | I40: =users[[#This Row],[paid_usd]]-users[[#This Row],[refunded_usd]] -> 0 | J40: =IF(users[[#This Row],[successful_payments_count]]>0,1,0) -> 0
A41: 40 | B41: 46164.784 | C41: BR | D41: tablet | E41: 1 | F41: =COUNTIFS(payments!$B$2:$B$203,A41,payments!$F$2:$F$203,"succeeded") -> 1 | G41: =SUMIFS(payments!$G$2:$G$203,payments!$F$2:$F$203,"succeeded",payments!$B$2:$B$203,A41) -> 19.99 | H41: =SUMIF(refunds!$G$2:$G$15,A41,refunds!$D$2:$D$15) -> 0 | I41: =users[[#This Row],[paid_usd]]-users[[#This Row],[refunded_usd]] -> 19.99 | J41: =IF(users[[#This Row],[successful_payments_count]]>0,1,0) -> 1
A42: 41 | B42: 46183.173 | C42: GB | D42: tablet | E42: 1 | F42: =COUNTIFS(payments!$B$2:$B$203,A42,payments!$F$2:$F$203,"succeeded") -> 1 | G42: =SUMIFS(payments!$G$2:$G$203,payments!$F$2:$F$203,"succeeded",payments!$B$2:$B$203,A42) -> 19.99 | H42: =SUMIF(refunds!$G$2:$G$15,A42,refunds!$D$2:$D$15) -> 0 | I42: =users[[#This Row],[paid_usd]]-users[[#This Row],[refunded_usd]] -> 19.99 | J42: =IF(users[[#This Row],[successful_payments_count]]>0,1,0) -> 1
...

Sheet payments
A1: payment_id | B1: user_id | C1: package_id | D1: attempted_at | E1: completed_at | F1: status | G1: amount_usd | H1: coins_granted | I1: country_code | J1: device_type | K1: Package_type (XLOOKUP) | L1: Package_type_(INDEX+MATCH) | M1: paid_usd | N1: is_us_mobile_or_tablet | O1: has_refunded | P1: refunded_sum | Q1: month
A2: 188 | B2: 1 | C2: 1 | D2: 46203.999 | F2: pending | G2: 4.99 | H2: 0 | I2: =_xlfn.XLOOKUP(B2,users!A:A,users!C:C) -> BR | J2: =_xlfn.XLOOKUP(B2,users!A:A,users!D:D) -> desktop | K2: =_xlfn.XLOOKUP(C2,coin_packages!A:A,coin_packages!B:B) -> Small | L2: {=INDEX(coin_packages!$B$2:$B$5,MATCH(C2,coin_packages!$A$2:$A$5,0))} -> Small | M2: =IF(F2="succeeded",G2,0) -> 0 | N2: =AND(F2="succeeded",I2="US",OR(J2="tablet",J2="mobile")) -> FALSE | O2: =COUNTIF(refunds!$B$2:$B$15,A2)>0 -> FALSE | P2: =_xlfn.XLOOKUP(A2,refunds!$B$2:$B$15,refunds!$D$2:$D$15,0,0) -> 0 | Q2: =IF(OR(payments[[#This Row],[completed_at]]="",payments[[#This Row],[completed_at]]=0),"",TEXT(payments[[#This Row],[completed_at]],"yyyy-mm"))
A3: 1 | B3: 1 | C3: 2 | D3: 46176.165 | E3: 46176.165 | F3: succeeded | G3: 9.99 | H3: 250 | I3: =_xlfn.XLOOKUP(B3,users!A:A,users!C:C) -> BR | J3: =_xlfn.XLOOKUP(B3,users!A:A,users!D:D) -> desktop | K3: =_xlfn.XLOOKUP(C3,coin_packages!A:A,coin_packages!B:B) -> Medium | L3: {=INDEX(coin_packages!$B$2:$B$5,MATCH(C3,coin_packages!$A$2:$A$5,0))} -> Medium | M3: =IF(F3="succeeded",G3,0) -> 9.99 | N3: =AND(F3="succeeded",I3="US",OR(J3="tablet",J3="mobile")) -> FALSE | O3: =COUNTIF(refunds!$B$2:$B$15,A3)>0 -> FALSE | P3: =_xlfn.XLOOKUP(A3,refunds!$B$2:$B$15,refunds!$D$2:$D$15,0,0) -> 0 | Q3: =IF(OR(payments[[#This Row],[completed_at]]="",payments[[#This Row],[completed_at]]=0),"",TEXT(payments[[#This Row],[completed_at]],"yyyy-mm")) -> 2026-06
A4: 189 | B4: 2 | C4: 1 | D4: 46203.999 | F4: pending | G4: 4.99 | H4: 0 | I4: =_xlfn.XLOOKUP(B4,users!A:A,users!C:C) -> US | J4: =_xlfn.XLOOKUP(B4,users!A:A,users!D:D) -> tablet | K4: =_xlfn.XLOOKUP(C4,coin_packages!A:A,coin_packages!B:B) -> Small | L4: {=INDEX(coin_packages!$B$2:$B$5,MATCH(C4,coin_packages!$A$2:$A$5,0))} -> Small | M4: =IF(F4="succeeded",G4,0) -> 0 | N4: =AND(F4="succeeded",I4="US",OR(J4="tablet",J4="mobile")) -> FALSE | O4: =COUNTIF(refunds!$B$2:$B$15,A4)>0 -> FALSE | P4: =_xlfn.XLOOKUP(A4,refunds!$B$2:$B$15,refunds!$D$2:$D$15,0,0) -> 0 | Q4: =IF(OR(payments[[#This Row],[completed_at]]="",payments[[#This Row],[completed_at]]=0),"",TEXT(payments[[#This Row],[completed_at]],"yyyy-mm"))
A5: 190 | B5: 3 | C5: 1 | D5: 46203.999 | F5: pending | G5: 4.99 | H5: 0 | I5: =_xlfn.XLOOKUP(B5,users!A:A,users!C:C) -> CA | J5: =_xlfn.XLOOKUP(B5,users!A:A,users!D:D) -> mobile | K5: =_xlfn.XLOOKUP(C5,coin_packages!A:A,coin_packages!B:B) -> Small | L5: {=INDEX(coin_packages!$B$2:$B$5,MATCH(C5,coin_packages!$A$2:$A$5,0))} -> Small | M5: =IF(F5="succeeded",G5,0) -> 0 | N5: =AND(F5="succeeded",I5="US",OR(J5="tablet",J5="mobile")) -> FALSE | O5: =COUNTIF(refunds!$B$2:$B$15,A5)>0 -> FALSE | P5: =_xlfn.XLOOKUP(A5,refunds!$B$2:$B$15,refunds!$D$2:$D$15,0,0) -> 0 | Q5: =IF(OR(payments[[#This Row],[completed_at]]="",payments[[#This Row],[completed_at]]=0),"",TEXT(payments[[#This Row],[completed_at]],"yyyy-mm"))
A6: 191 | B6: 4 | C6: 1 | D6: 46203.999 | F6: pending | G6: 4.99 | H6: 0 | I6: =_xlfn.XLOOKUP(B6,users!A:A,users!C:C) -> DE | J6: =_xlfn.XLOOKUP(B6,users!A:A,users!D:D) -> mobile | K6: =_xlfn.XLOOKUP(C6,coin_packages!A:A,coin_packages!B:B) -> Small | L6: {=INDEX(coin_packages!$B$2:$B$5,MATCH(C6,coin_packages!$A$2:$A$5,0))} -> Small | M6: =IF(F6="succeeded",G6,0) -> 0 | N6: =AND(F6="succeeded",I6="US",OR(J6="tablet",J6="mobile")) -> FALSE | O6: =COUNTIF(refunds!$B$2:$B$15,A6)>0 -> FALSE | P6: =_xlfn.XLOOKUP(A6,refunds!$B$2:$B$15,refunds!$D$2:$D$15,0,0) -> 0 | Q6: =IF(OR(payments[[#This Row],[completed_at]]="",payments[[#This Row],[completed_at]]=0),"",TEXT(payments[[#This Row],[completed_at]],"yyyy-mm"))
A7: 192 | B7: 5 | C7: 1 | D7: 46203.999 | F7: pending | G7: 4.99 | H7: 0 | I7: =_xlfn.XLOOKUP(B7,users!A:A,users!C:C) -> CA | J7: =_xlfn.XLOOKUP(B7,users!A:A,users!D:D) -> mobile | K7: =_xlfn.XLOOKUP(C7,coin_packages!A:A,coin_packages!B:B) -> Small | L7: {=INDEX(coin_packages!$B$2:$B$5,MATCH(C7,coin_packages!$A$2:$A$5,0))} -> Small | M7: =IF(F7="succeeded",G7,0) -> 0 | N7: =AND(F7="succeeded",I7="US",OR(J7="tablet",J7="mobile")) -> FALSE | O7: =COUNTIF(refunds!$B$2:$B$15,A7)>0 -> FALSE | P7: =_xlfn.XLOOKUP(A7,refunds!$B$2:$B$15,refunds!$D$2:$D$15,0,0) -> 0 | Q7: =IF(OR(payments[[#This Row],[completed_at]]="",payments[[#This Row],[completed_at]]=0),"",TEXT(payments[[#This Row],[completed_at]],"yyyy-mm"))
A8: 2 | B8: 5 | C8: 2 | D8: 46192.672 | E8: 46192.672 | F8: succeeded | G8: 9.99 | H8: 250 | I8: =_xlfn.XLOOKUP(B8,users!A:A,users!C:C) -> CA | J8: =_xlfn.XLOOKUP(B8,users!A:A,users!D:D) -> mobile | K8: =_xlfn.XLOOKUP(C8,coin_packages!A:A,coin_packages!B:B) -> Medium | L8: {=INDEX(coin_packages!$B$2:$B$5,MATCH(C8,coin_packages!$A$2:$A$5,0))} -> Medium | M8: =IF(F8="succeeded",G8,0) -> 9.99 | N8: =AND(F8="succeeded",I8="US",OR(J8="tablet",J8="mobile")) -> FALSE | O8: =COUNTIF(refunds!$B$2:$B$15,A8)>0 -> FALSE | P8: =_xlfn.XLOOKUP(A8,refunds!$B$2:$B$15,refunds!$D$2:$D$15,0,0) -> 0 | Q8: =IF(OR(payments[[#This Row],[completed_at]]="",payments[[#This Row],[completed_at]]=0),"",TEXT(payments[[#This Row],[completed_at]],"yyyy-mm")) -> 2026-06
A9: 193 | B9: 6 | C9: 1 | D9: 46203.999 | F9: pending | G9: 4.99 | H9: 0 | I9: =_xlfn.XLOOKUP(B9,users!A:A,users!C:C) -> GB | J9: =_xlfn.XLOOKUP(B9,users!A:A,users!D:D) -> tablet | K9: =_xlfn.XLOOKUP(C9,coin_packages!A:A,coin_packages!B:B) -> Small | L9: {=INDEX(coin_packages!$B$2:$B$5,MATCH(C9,coin_packages!$A$2:$A$5,0))} -> Small | M9: =IF(F9="succeeded",G9,0) -> 0 | N9: =AND(F9="succeeded",I9="US",OR(J9="tablet",J9="mobile")) -> FALSE | O9: =COUNTIF(refunds!$B$2:$B$15,A9)>0 -> FALSE | P9: =_xlfn.XLOOKUP(A9,refunds!$B$2:$B$15,refunds!$D$2:$D$15,0,0) -> 0 | Q9: =IF(OR(payments[[#This Row],[completed_at]]="",payments[[#This Row],[completed_at]]=0),"",TEXT(payments[[#This Row],[completed_at]],"yyyy-mm"))
A10: 194 | B10: 7 | C10: 1 | D10: 46203.999 | F10: pending | G10: 4.99 | H10: 0 | I10: =_xlfn.XLOOKUP(B10,users!A:A,users!C:C) -> US | J10: =_xlfn.XLOOKUP(B10,users!A:A,users!D:D) -> tablet | K10: =_xlfn.XLOOKUP(C10,coin_packages!A:A,coin_packages!B:B) -> Small | L10: {=INDEX(coin_packages!$B$2:$B$5,MATCH(C10,coin_packages!$A$2:$A$5,0))} -> Small | M10: =IF(F10="succeeded",G10,0) -> 0 | N10: =AND(F10="succeeded",I10="US",OR(J10="tablet",J10="mobile")) -> FALSE | O10: =COUNTIF(refunds!$B$2:$B$15,A10)>0 -> FALSE | P10: =_xlfn.XLOOKUP(A10,refunds!$B$2:$B$15,refunds!$D$2:$D$15,0,0) -> 0 | Q10: =IF(OR(payments[[#This Row],[completed_at]]="",payments[[#This Row],[completed_at]]=0),"",TEXT(payments[[#This Row],[completed_at]],"yyyy-mm"))
A11: 195 | B11: 8 | C11: 1 | D11: 46203.999 | F11: pending | G11: 4.99 | H11: 0 | I11: =_xlfn.XLOOKUP(B11,users!A:A,users!C:C) -> CA | J11: =_xlfn.XLOOKUP(B11,users!A:A,users!D:D) -> desktop | K11: =_xlfn.XLOOKUP(C11,coin_packages!A:A,coin_packages!B:B) -> Small | L11: {=INDEX(coin_packages!$B$2:$B$5,MATCH(C11,coin_packages!$A$2:$A$5,0))} -> Small | M11: =IF(F11="succeeded",G11,0) -> 0 | N11: =AND(F11="succeeded",I11="US",OR(J11="tablet",J11="mobile")) -> FALSE | O11: =COUNTIF(refunds!$B$2:$B$15,A11)>0 -> FALSE | P11: =_xlfn.XLOOKUP(A11,refunds!$B$2:$B$15,refunds!$D$2:$D$15,0,0) -> 0 | Q11: =IF(OR(payments[[#This Row],[completed_at]]="",payments[[#This Row],[completed_at]]=0),"",TEXT(payments[[#This Row],[completed_at]],"yyyy-mm"))
A12: 3 | B12: 8 | C12: 1 | D12: 46088.445 | E12: 46088.445 | F12: succeeded | G12: 4.99 | H12: 100 | I12: =_xlfn.XLOOKUP(B12,users!A:A,users!C:C) -> CA | J12: =_xlfn.XLOOKUP(B12,users!A:A,users!D:D) -> desktop | K12: =_xlfn.XLOOKUP(C12,coin_packages!A:A,coin_packages!B:B) -> Small | L12: {=INDEX(coin_packages!$B$2:$B$5,MATCH(C12,coin_packages!$A$2:$A$5,0))} -> Small | M12: =IF(F12="succeeded",G12,0) -> 4.99 | N12: =AND(F12="succeeded",I12="US",OR(J12="tablet",J12="mobile")) -> FALSE | O12: =COUNTIF(refunds!$B$2:$B$15,A12)>0 -> FALSE | P12: =_xlfn.XLOOKUP(A12,refunds!$B$2:$B$15,refunds!$D$2:$D$15,0,0) -> 0 | Q12: =IF(OR(payments[[#This Row],[completed_at]]="",payments[[#This Row],[completed_at]]=0),"",TEXT(payments[[#This Row],[completed_at]],"yyyy-mm")) -> 2026-03
A13: 196 | B13: 9 | C13: 1 | D13: 46203.999 | F13: pending | G13: 4.99 | H13: 0 | I13: =_xlfn.XLOOKUP(B13,users!A:A,users!C:C) -> BR | J13: =_xlfn.XLOOKUP(B13,users!A:A,users!D:D) -> tablet | K13: =_xlfn.XLOOKUP(C13,coin_packages!A:A,coin_packages!B:B) -> Small | L13: {=INDEX(coin_packages!$B$2:$B$5,MATCH(C13,coin_packages!$A$2:$A$5,0))} -> Small | M13: =IF(F13="succeeded",G13,0) -> 0 | N13: =AND(F13="succeeded",I13="US",OR(J13="tablet",J13="mobile")) -> FALSE | O13: =COUNTIF(refunds!$B$2:$B$15,A13)>0 -> FALSE | P13: =_xlfn.XLOOKUP(A13,refunds!$B$2:$B$15,refunds!$D$2:$D$15,0,0) -> 0 | Q13: =IF(OR(payments[[#This Row],[completed_at]]="",payments[[#This Row],[completed_at]]=0),"",TEXT(payments[[#This Row],[completed_at]],"yyyy-mm"))
A14: 197 | B14: 10 | C14: 1 | D14: 46203.999 | F14: pending | G14: 4.99 | H14: 0 | I14: =_xlfn.XLOOKUP(B14,users!A:A,users!C:C) -> BR | J14: =_xlfn.XLOOKUP(B14,users!A:A,users!D:D) -> desktop | K14: =_xlfn.XLOOKUP(C14,coin_packages!A:A,coin_packages!B:B) -> Small | L14: {=INDEX(coin_packages!$B$2:$B$5,MATCH(C14,coin_packages!$A$2:$A$5,0))} -> Small | M14: =IF(F14="succeeded",G14,0) -> 0 | N14: =AND(F14="succeeded",I14="US",OR(J14="tablet",J14="mobile")) -> FALSE | O14: =COUNTIF(refunds!$B$2:$B$15,A14)>0 -> FALSE | P14: =_xlfn.XLOOKUP(A14,refunds!$B$2:$B$15,refunds!$D$2:$D$15,0,0) -> 0 | Q14: =IF(OR(payments[[#This Row],[completed_at]]="",payments[[#This Row],[completed_at]]=0),"",TEXT(payments[[#This Row],[completed_at]],"yyyy-mm"))
A15: 198 | B15: 11 | C15: 1 | D15: 46203.999 | F15: pending | G15: 4.99 | H15: 0 | I15: =_xlfn.XLOOKUP(B15,users!A:A,users!C:C) -> UA | J15: =_xlfn.XLOOKUP(B15,users!A:A,users!D:D) -> mobile | K15: =_xlfn.XLOOKUP(C15,coin_packages!A:A,coin_packages!B:B) -> Small | L15: {=INDEX(coin_packages!$B$2:$B$5,MATCH(C15,coin_packages!$A$2:$A$5,0))} -> Small | M15: =IF(F15="succeeded",G15,0) -> 0 | N15: =AND(F15="succeeded",I15="US",OR(J15="tablet",J15="mobile")) -> FALSE | O15: =COUNTIF(refunds!$B$2:$B$15,A15)>0 -> FALSE | P15: =_xlfn.XLOOKUP(A15,refunds!$B$2:$B$15,refunds!$D$2:$D$15,0,0) -> 0 | Q15: =IF(OR(payments[[#This Row],[completed_at]]="",payments[[#This Row],[completed_at]]=0),"",TEXT(payments[[#This Row],[completed_at]],"yyyy-mm"))
A16: 199 | B16: 12 | C16: 1 | D16: 46203.999 | F16: pending | G16: 4.99 | H16: 0 | I16: =_xlfn.XLOOKUP(B16,users!A:A,users!C:C) -> DE | J16: =_xlfn.XLOOKUP(B16,users!A:A,users!D:D) -> mobile | K16: =_xlfn.XLOOKUP(C16,coin_packages!A:A,coin_packages!B:B) -> Small | L16: {=INDEX(coin_packages!$B$2:$B$5,MATCH(C16,coin_packages!$A$2:$A$5,0))} -> Small | M16: =IF(F16="succeeded",G16,0) -> 0 | N16: =AND(F16="succeeded",I16="US",OR(J16="tablet",J16="mobile")) -> FALSE | O16: =COUNTIF(refunds!$B$2:$B$15,A16)>0 -> FALSE | P16: =_xlfn.XLOOKUP(A16,refunds!$B$2:$B$15,refunds!$D$2:$D$15,0,0) -> 0 | Q16: =IF(OR(payments[[#This Row],[completed_at]]="",payments[[#This Row],[completed_at]]=0),"",TEXT(payments[[#This Row],[completed_at]],"yyyy-mm"))
A17: 200 | B17: 13 | C17: 1 | D17: 46203.999 | F17: pending | G17: 4.99 | H17: 0 | I17: =_xlfn.XLOOKUP(B17,users!A:A,users!C:C) -> UA | J17: =_xlfn.XLOOKUP(B17,users!A:A,users!D:D) -> tablet | K17: =_xlfn.XLOOKUP(C17,coin_packages!A:A,coin_packages!B:B) -> Small | L17: {=INDEX(coin_packages!$B$2:$B$5,MATCH(C17,coin_packages!$A$2:$A$5,0))} -> Small | M17: =IF(F17="succeeded",G17,0) -> 0 | N17: =AND(F17="succeeded",I17="US",OR(J17="tablet",J17="mobile")) -> FALSE | O17: =COUNTIF(refunds!$B$2:$B$15,A17)>0 -> FALSE | P17: =_xlfn.XLOOKUP(A17,refunds!$B$2:$B$15,refunds!$D$2:$D$15,0,0) -> 0 | Q17: =IF(OR(payments[[#This Row],[completed_at]]="",payments[[#This Row],[completed_at]]=0),"",TEXT(payments[[#This Row],[completed_at]],"yyyy-mm"))
A18: 4 | B18: 13 | C18: 2 | D18: 46128.645 | E18: 46128.645 | F18: succeeded | G18: 7.99 | H18: 250 | I18: =_xlfn.XLOOKUP(B18,users!A:A,users!C:C) -> UA | J18: =_xlfn.XLOOKUP(B18,users!A:A,users!D:D) -> tablet | K18: =_xlfn.XLOOKUP(C18,coin_packages!A:A,coin_packages!B:B) -> Medium | L18: {=INDEX(coin_packages!$B$2:$B$5,MATCH(C18,coin_packages!$A$2:$A$5,0))} -> Medium | M18: =IF(F18="succeeded",G18,0) -> 7.99 | N18: =AND(F18="succeeded",I18="US",OR(J18="tablet",J18="mobile")) -> FALSE | O18: =COUNTIF(refunds!$B$2:$B$15,A18)>0 -> FALSE | P18: =_xlfn.XLOOKUP(A18,refunds!$B$2:$B$15,refunds!$D$2:$D$15,0,0) -> 0 | Q18: =IF(OR(payments[[#This Row],[completed_at]]="",payments[[#This Row],[completed_at]]=0),"",TEXT(payments[[#This Row],[completed_at]],"yyyy-mm")) -> 2026-04
A19: 201 | B19: 14 | C19: 1 | D19: 46203.999 | F19: pending | G19: 4.99 | H19: 0 | I19: =_xlfn.XLOOKUP(B19,users!A:A,users!C:C) -> BR | J19: =_xlfn.XLOOKUP(B19,users!A:A,users!D:D) -> tablet | K19: =_xlfn.XLOOKUP(C19,coin_packages!A:A,coin_packages!B:B) -> Small | L19: {=INDEX(coin_packages!$B$2:$B$5,MATCH(C19,coin_packages!$A$2:$A$5,0))} -> Small | M19: =IF(F19="succeeded",G19,0) -> 0 | N19: =AND(F19="succeeded",I19="US",OR(J19="tablet",J19="mobile")) -> FALSE | O19: =COUNTIF(refunds!$B$2:$B$15,A19)>0 -> FALSE | P19: =_xlfn.XLOOKUP(A19,refunds!$B$2:$B$15,refunds!$D$2:$D$15,0,0) -> 0 | Q19: =IF(OR(payments[[#This Row],[completed_at]]="",payments[[#This Row],[completed_at]]=0),"",TEXT(payments[[#This Row],[completed_at]],"yyyy-mm"))
A20: 202 | B20: 15 | C20: 1 | D20: 46203.999 | F20: pending | G20: 4.99 | H20: 0 | I20: =_xlfn.XLOOKUP(B20,users!A:A,users!C:C) -> CA | J20: =_xlfn.XLOOKUP(B20,users!A:A,users!D:D) -> mobile | K20: =_xlfn.XLOOKUP(C20,coin_packages!A:A,coin_packages!B:B) -> Small | L20: {=INDEX(coin_packages!$B$2:$B$5,MATCH(C20,coin_packages!$A$2:$A$5,0))} -> Small | M20: =IF(F20="succeeded",G20,0) -> 0 | N20: =AND(F20="succeeded",I20="US",OR(J20="tablet",J20="mobile")) -> FALSE | O20: =COUNTIF(refunds!$B$2:$B$15,A20)>0 -> FALSE | P20: =_xlfn.XLOOKUP(A20,refunds!$B$2:$B$15,refunds!$D$2:$D$15,0,0) -> 0 | Q20: =IF(OR(payments[[#This Row],[completed_at]]="",payments[[#This Row],[completed_at]]=0),"",TEXT(payments[[#This Row],[completed_at]],"yyyy-mm"))
A21: 5 | B21: 36 | C21: 2 | D21: 46150.419 | E21: 46150.419 | F21: succeeded | G21: 7.99 | H21: 250 | I21: =_xlfn.XLOOKUP(B21,users!A:A,users!C:C) -> US | J21: =_xlfn.XLOOKUP(B21,users!A:A,users!D:D) -> mobile | K21: =_xlfn.XLOOKUP(C21,coin_packages!A:A,coin_packages!B:B) -> Medium | L21: {=INDEX(coin_packages!$B$2:$B$5,MATCH(C21,coin_packages!$A$2:$A$5,0))} -> Medium | M21: =IF(F21="succeeded",G21,0) -> 7.99 | N21: =AND(F21="succeeded",I21="US",OR(J21="tablet",J21="mobile")) -> TRUE | O21: =COUNTIF(refunds!$B$2:$B$15,A21)>0 -> FALSE | P21: =_xlfn.XLOOKUP(A21,refunds!$B$2:$B$15,refunds!$D$2:$D$15,0,0) -> 0 | Q21: =IF(OR(payments[[#This Row],[completed_at]]="",payments[[#This Row],[completed_at]]=0),"",TEXT(payments[[#This Row],[completed_at]],"yyyy-mm")) -> 2026-05
A22: 6 | B22: 40 | C22: 3 | D22: 46192.339 | E22: 46192.339 | F22: succeeded | G22: 19.99 | H22: 600 | I22: =_xlfn.XLOOKUP(B22,users!A:A,users!C:C) -> BR | J22: =_xlfn.XLOOKUP(B22,users!A:A,users!D:D) -> tablet | K22: =_xlfn.XLOOKUP(C22,coin_packages!A:A,coin_packages!B:B) -> Large | L22: {=INDEX(coin_packages!$B$2:$B$5,MATCH(C22,coin_packages!$A$2:$A$5,0))} -> Large | M22: =IF(F22="succeeded",G22,0) -> 19.99 | N22: =AND(F22="succeeded",I22="US",OR(J22="tablet",J22="mobile")) -> FALSE | O22: =COUNTIF(refunds!$B$2:$B$15,A22)>0 -> FALSE | P22: =_xlfn.XLOOKUP(A22,refunds!$B$2:$B$15,refunds!$D$2:$D$15,0,0) -> 0 | Q22: =IF(OR(payments[[#This Row],[completed_at]]="",payments[[#This Row],[completed_at]]=0),"",TEXT(payments[[#This Row],[completed_at]],"yyyy-mm")) -> 2026-06
A23: 7 | B23: 41 | C23: 3 | D23: 46196.551 | E23: 46196.551 | F23: succeeded | G23: 19.99 | H23: 600 | I23: =_xlfn.XLOOKUP(B23,users!A:A,users!C:C) -> GB | J23: =_xlfn.XLOOKUP(B23,users!A:A,users!D:D) -> tablet | K23: =_xlfn.XLOOKUP(C23,coin_packages!A:A,coin_packages!B:B) -> Large | L23: {=INDEX(coin_packages!$B$2:$B$5,MATCH(C23,coin_packages!$A$2:$A$5,0))} -> Large | M23: =IF(F23="succeeded",G23,0) -> 19.99 | N23: =AND(F23="succeeded",I23="US",OR(J23="tablet",J23="mobile")) -> FALSE | O23: =COUNTIF(refunds!$B$2:$B$15,A23)>0 -> FALSE | P23: =_xlfn.XLOOKUP(A23,refunds!$B$2:$B$15,refunds!$D$2:$D$15,0,0) -> 0 | Q23: =IF(OR(payments[[#This Row],[completed_at]]="",payments[[#This Row],[completed_at]]=0),"",TEXT(payments[[#This Row],[completed_at]],"yyyy-mm")) -> 2026-06
A24: 8 | B24: 42 | C24: 3 | D24: 46144.51 | E24: 46144.51 | F24: succeeded | G24: 19.99 | H24: 600 | I24: =_xlfn.XLOOKUP(B24,users!A:A,users!C:C) -> GB | J24: =_xlfn.XLOOKUP(B24,users!A:A,users!D:D) -> tablet | K24: =_xlfn.XLOOKUP(C24,coin_packages!A:A,coin_packages!B:B) -> Large | L24: {=INDEX(coin_packages!$B$2:$B$5,MATCH(C24,coin_packages!$A$2:$A$5,0))} -> Large | M24: =IF(F24="succeeded",G24,0) -> 19.99 | N24: =AND(F24="succeeded",I24="US",OR(J24="tablet",J24="mobile")) -> FALSE | O24: =COUNTIF(refunds!$B$2:$B$15,A24)>0 -> FALSE | P24: =_xlfn.XLOOKUP(A24,refunds!$B$2:$B$15,refunds!$D$2:$D$15,0,0) -> 0 | Q24: =IF(OR(payments[[#This Row],[completed_at]]="",payments[[#This Row],[completed_at]]=0),"",TEXT(payments[[#This Row],[completed_at]],"yyyy-mm")) -> 2026-05
A25: 10 | B25: 49 | C25: 1 | D25: 46137.062 | E25: 46137.062 | F25: succeeded | G25: 4.99 | H25: 100 | I25: =_xlfn.XLOOKUP(B25,users!A:A,users!C:C) -> CA | J25: =_xlfn.XLOOKUP(B25,users!A:A,users!D:D) -> mobile | K25: =_xlfn.XLOOKUP(C25,coin_packages!A:A,coin_packages!B:B) -> Small | L25: {=INDEX(coin_packages!$B$2:$B$5,MATCH(C25,coin_packages!$A$2:$A$5,0))} -> Small | M25: =IF(F25="succeeded",G25,0) -> 4.99 | N25: =AND(F25="succeeded",I25="US",OR(J25="tablet",J25="mobile")) -> FALSE | O25: =COUNTIF(refunds!$B$2:$B$15,A25)>0 -> FALSE | P25: =_xlfn.XLOOKUP(A25,refunds!$B$2:$B$15,refunds!$D$2:$D$15,0,0) -> 0 | Q25: =IF(OR(payments[[#This Row],[completed_at]]="",payments[[#This Row],[completed_at]]=0),"",TEXT(payments[[#This Row],[completed_at]],"yyyy-mm")) -> 2026-04
A26: 9 | B26: 49 | C26: 2 | D26: 46136.875 | E26: 46136.875 | F26: succeeded | G26: 9.99 | H26: 250 | I26: =_xlfn.XLOOKUP(B26,users!A:A,users!C:C) -> CA | J26: =_xlfn.XLOOKUP(B26,users!A:A,users!D:D) -> mobile | K26: =_xlfn.XLOOKUP(C26,coin_packages!A:A,coin_packages!B:B) -> Medium | L26: {=INDEX(coin_packages!$B$2:$B$5,MATCH(C26,coin_packages!$A$2:$A$5,0))} -> Medium | M26: =IF(F26="succeeded",G26,0) -> 9.99 | N26: =AND(F26="succeeded",I26="US",OR(J26="tablet",J26="mobile")) -> FALSE | O26: =COUNTIF(refunds!$B$2:$B$15,A26)>0 -> TRUE | P26: =_xlfn.XLOOKUP(A26,refunds!$B$2:$B$15,refunds!$D$2:$D$15,0,0) -> 9.99 | Q26: =IF(OR(payments[[#This Row],[completed_at]]="",payments[[#This Row],[completed_at]]=0),"",TEXT(payments[[#This Row],[completed_at]],"yyyy-mm")) -> 2026-04
A27: 11 | B27: 56 | C27: 1 | D27: 46129.993 | E27: 46129.993 | F27: succeeded | G27: 4.99 | H27: 100 | I27: =_xlfn.XLOOKUP(B27,users!A:A,users!C:C) -> US | J27: =_xlfn.XLOOKUP(B27,users!A:A,users!D:D) -> desktop | K27: =_xlfn.XLOOKUP(C27,coin_packages!A:A,coin_packages!B:B) -> Small | L27: {=INDEX(coin_packages!$B$2:$B$5,MATCH(C27,coin_packages!$A$2:$A$5,0))} -> Small | M27: =IF(F27="succeeded",G27,0) -> 4.99 | N27: =AND(F27="succeeded",I27="US",OR(J27="tablet",J27="mobile")) -> FALSE | O27: =COUNTIF(refunds!$B$2:$B$15,A27)>0 -> FALSE | P27: =_xlfn.XLOOKUP(A27,refunds!$B$2:$B$15,refunds!$D$2:$D$15,0,0) -> 0 | Q27: =IF(OR(payments[[#This Row],[completed_at]]="",payments[[#This Row],[completed_at]]=0),"",TEXT(payments[[#This Row],[completed_at]],"yyyy-mm")) -> 2026-04
A28: 12 | B28: 57 | C28: 2 | D28: 46145.645 | E28: 46145.646 | F28: succeeded | G28: 9.99 | H28: 250 | I28: =_xlfn.XLOOKUP(B28,users!A:A,users!C:C) -> GB | J28: =_xlfn.XLOOKUP(B28,users!A:A,users!D:D) -> tablet | K28: =_xlfn.XLOOKUP(C28,coin_packages!A:A,coin_packages!B:B) -> Medium | L28: {=INDEX(coin_packages!$B$2:$B$5,MATCH(C28,coin_packages!$A$2:$A$5,0))} -> Medium | M28: =IF(F28="succeeded",G28,0) -> 9.99 | N28: =AND(F28="succeeded",I28="US",OR(J28="tablet",J28="mobile")) -> FALSE | O28: =COUNTIF(refunds!$B$2:$B$15,A28)>0 -> FALSE | P28: =_xlfn.XLOOKUP(A28,refunds!$B$2:$B$15,refunds!$D$2:$D$15,0,0) -> 0 | Q28: =IF(OR(payments[[#This Row],[completed_at]]="",payments[[#This Row],[completed_at]]=0),"",TEXT(payments[[#This Row],[completed_at]],"yyyy-mm")) -> 2026-05
A29: 13 | B29: 58 | C29: 3 | D29: 46066.091 | E29: 46066.092 | F29: succeeded | G29: 19.99 | H29: 600 | I29: =_xlfn.XLOOKUP(B29,users!A:A,users!C:C) -> CA | J29: =_xlfn.XLOOKUP(B29,users!A:A,users!D:D) -> desktop | K29: =_xlfn.XLOOKUP(C29,coin_packages!A:A,coin_packages!B:B) -> Large | L29: {=INDEX(coin_packages!$B$2:$B$5,MATCH(C29,coin_packages!$A$2:$A$5,0))} -> Large | M29: =IF(F29="succeeded",G29,0) -> 19.99 | N29: =AND(F29="succeeded",I29="US",OR(J29="tablet",J29="mobile")) -> FALSE | O29: =COUNTIF(refunds!$B$2:$B$15,A29)>0 -> FALSE | P29: =_xlfn.XLOOKUP(A29,refunds!$B$2:$B$15,refunds!$D$2:$D$15,0,0) -> 0 | Q29: =IF(OR(payments[[#This Row],[completed_at]]="",payments[[#This Row],[completed_at]]=0),"",TEXT(payments[[#This Row],[completed_at]],"yyyy-mm")) -> 2026-02
A30: 14 | B30: 65 | C30: 1 | D30: 46169.21 | E30: 46169.21 | F30: succeeded | G30: 4.99 | H30: 100 | I30: =_xlfn.XLOOKUP(B30,users!A:A,users!C:C) -> CA | J30: =_xlfn.XLOOKUP(B30,users!A:A,users!D:D) -> mobile | K30: =_xlfn.XLOOKUP(C30,coin_packages!A:A,coin_packages!B:B) -> Small | L30: {=INDEX(coin_packages!$B$2:$B$5,MATCH(C30,coin_packages!$A$2:$A$5,0))} -> Small | M30: =IF(F30="succeeded",G30,0) -> 4.99 | N30: =AND(F30="succeeded",I30="US",OR(J30="tablet",J30="mobile")) -> FALSE | O30: =COUNTIF(refunds!$B$2:$B$15,A30)>0 -> FALSE | P30: =_xlfn.XLOOKUP(A30,refunds!$B$2:$B$15,refunds!$D$2:$D$15,0,0) -> 0 | Q30: =IF(OR(payments[[#This Row],[completed_at]]="",payments[[#This Row],[completed_at]]=0),"",TEXT(payments[[#This Row],[completed_at]],"yyyy-mm")) -> 2026-05
A31: 15 | B31: 66 | C31: 2 | D31: 46126.526 | E31: 46126.527 | F31: succeeded | G31: 9.99 | H31: 250 | I31: =_xlfn.XLOOKUP(B31,users!A:A,users!C:C) -> DE | J31: =_xlfn.XLOOKUP(B31,users!A:A,users!D:D) -> desktop | K31: =_xlfn.XLOOKUP(C31,coin_packages!A:A,coin_packages!B:B) -> Medium | L31: {=INDEX(coin_packages!$B$2:$B$5,MATCH(C31,coin_packages!$A$2:$A$5,0))} -> Medium | M31: =IF(F31="succeeded",G31,0) -> 9.99 | N31: =AND(F31="succeeded",I31="US",OR(J31="tablet",J31="mobile")) -> FALSE | O31: =COUNTIF(refunds!$B$2:$B$15,A31)>0 -> FALSE | P31: =_xlfn.XLOOKUP(A31,refunds!$B$2:$B$15,refunds!$D$2:$D$15,0,0) -> 0 | Q31: =IF(OR(payments[[#This Row],[completed_at]]="",payments[[#This Row],[completed_at]]=0),"",TEXT(payments[[#This Row],[completed_at]],"yyyy-mm")) -> 2026-04
A32: 16 | B32: 67 | C32: 3 | D32: 46086.51 | E32: 46086.51 | F32: succeeded | G32: 19.99 | H32: 600 | I32: =_xlfn.XLOOKUP(B32,users!A:A,users!C:C) -> CA | J32: =_xlfn.XLOOKUP(B32,users!A:A,users!D:D) -> tablet | K32: =_xlfn.XLOOKUP(C32,coin_packages!A:A,coin_packages!B:B) -> Large | L32: {=INDEX(coin_packages!$B$2:$B$5,MATCH(C32,coin_packages!$A$2:$A$5,0))} -> Large | M32: =IF(F32="succeeded",G32,0) -> 19.99 | N32: =AND(F32="succeeded",I32="US",OR(J32="tablet",J32="mobile")) -> FALSE | O32: =COUNTIF(refunds!$B$2:$B$15,A32)>0 -> FALSE | P32: =_xlfn.XLOOKUP(A32,refunds!$B$2:$B$15,refunds!$D$2:$D$15,0,0) -> 0 | Q32: =IF(OR(payments[[#This Row],[completed_at]]="",payments[[#This Row],[completed_at]]=0),"",TEXT(payments[[#This Row],[completed_at]],"yyyy-mm")) -> 2026-03
A33: 18 | B33: 69 | C33: 3 | D33: 46115.379 | E33: 46115.379 | F33: succeeded | G33: 19.99 | H33: 600 | I33: =_xlfn.XLOOKUP(B33,users!A:A,users!C:C) -> BR | J33: =_xlfn.XLOOKUP(B33,users!A:A,users!D:D) -> mobile | K33: =_xlfn.XLOOKUP(C33,coin_packages!A:A,coin_packages!B:B) -> Large | L33: {=INDEX(coin_packages!$B$2:$B$5,MATCH(C33,coin_packages!$A$2:$A$5,0))} -> Large | M33: =IF(F33="succeeded",G33,0) -> 19.99 | N33: =AND(F33="succeeded",I33="US",OR(J33="tablet",J33="mobile")) -> FALSE | O33: =COUNTIF(refunds!$B$2:$B$15,A33)>0 -> FALSE | P33: =_xlfn.XLOOKUP(A33,refunds!$B$2:$B$15,refunds!$D$2:$D$15,0,0) -> 0 | Q33: =IF(OR(payments[[#This Row],[completed_at]]="",payments[[#This Row],[completed_at]]=0),"",TEXT(payments[[#This Row],[completed_at]],"yyyy-mm")) -> 2026-04
A34: 17 | B34: 69 | C34: 3 | D34: 46104.228 | F34: failed | G34: 19.99 | H34: 0 | I34: =_xlfn.XLOOKUP(B34,users!A:A,users!C:C) -> BR | J34: =_xlfn.XLOOKUP(B34,users!A:A,users!D:D) -> mobile | K34: =_xlfn.XLOOKUP(C34,coin_packages!A:A,coin_packages!B:B) -> Large | L34: {=INDEX(coin_packages!$B$2:$B$5,MATCH(C34,coin_packages!$A$2:$A$5,0))} -> Large | M34: =IF(F34="succeeded",G34,0) -> 0 | N34: =AND(F34="succeeded",I34="US",OR(J34="tablet",J34="mobile")) -> FALSE | O34: =COUNTIF(refunds!$B$2:$B$15,A34)>0 -> FALSE | P34: =_xlfn.XLOOKUP(A34,refunds!$B$2:$B$15,refunds!$D$2:$D$15,0,0) -> 0 | Q34: =IF(OR(payments[[#This Row],[completed_at]]="",payments[[#This Row],[completed_at]]=0),"",TEXT(payments[[#This Row],[completed_at]],"yyyy-mm"))
A35: 20 | B35: 70 | C35: 2 | D35: 46175.239 | E35: 46175.239 | F35: succeeded | G35: 7.99 | H35: 250 | I35: =_xlfn.XLOOKUP(B35,users!A:A,users!C:C) -> BR | J35: =_xlfn.XLOOKUP(B35,users!A:A,users!D:D) -> tablet | K35: =_xlfn.XLOOKUP(C35,coin_packages!A:A,coin_packages!B:B) -> Medium | L35: {=INDEX(coin_packages!$B$2:$B$5,MATCH(C35,coin_packages!$A$2:$A$5,0))} -> Medium | M35: =IF(F35="succeeded",G35,0) -> 7.99 | N35: =AND(F35="succeeded",I35="US",OR(J35="tablet",J35="mobile")) -> FALSE | O35: =COUNTIF(refunds!$B$2:$B$15,A35)>0 -> FALSE | P35: =_xlfn.XLOOKUP(A35,refunds!$B$2:$B$15,refunds!$D$2:$D$15,0,0) -> 0 | Q35: =IF(OR(payments[[#This Row],[completed_at]]="",payments[[#This Row],[completed_at]]=0),"",TEXT(payments[[#This Row],[completed_at]],"yyyy-mm")) -> 2026-06
A36: 19 | B36: 70 | C36: 1 | D36: 46151.04 | E36: 46151.04 | F36: succeeded | G36: 4.99 | H36: 100 | I36: =_xlfn.XLOOKUP(B36,users!A:A,users!C:C) -> BR | J36: =_xlfn.XLOOKUP(B36,users!A:A,users!D:D) -> tablet | K36: =_xlfn.XLOOKUP(C36,coin_packages!A:A,coin_packages!B:B) -> Small | L36: {=INDEX(coin_packages!$B$2:$B$5,MATCH(C36,coin_packages!$A$2:$A$5,0))} -> Small | M36: =IF(F36="succeeded",G36,0) -> 4.99 | N36: =AND(F36="succeeded",I36="US",OR(J36="tablet",J36="mobile")) -> FALSE | O36: =COUNTIF(refunds!$B$2:$B$15,A36)>0 -> FALSE | P36: =_xlfn.XLOOKUP(A36,refunds!$B$2:$B$15,refunds!$D$2:$D$15,0,0) -> 0 | Q36: =IF(OR(payments[[#This Row],[completed_at]]="",payments[[#This Row],[completed_at]]=0),"",TEXT(payments[[#This Row],[completed_at]],"yyyy-mm")) -> 2026-05
A37: 21 | B37: 76 | C37: 3 | D37: 46072.282 | E37: 46072.282 | F37: succeeded | G37: 15.99 | H37: 600 | I37: =_xlfn.XLOOKUP(B37,users!A:A,users!C:C) -> DE | J37: =_xlfn.XLOOKUP(B37,users!A:A,users!D:D) -> tablet | K37: =_xlfn.XLOOKUP(C37,coin_packages!A:A,coin_packages!B:B) -> Large | L37: {=INDEX(coin_packages!$B$2:$B$5,MATCH(C37,coin_packages!$A$2:$A$5,0))} -> Large | M37: =IF(F37="succeeded",G37,0) -> 15.99 | N37: =AND(F37="succeeded",I37="US",OR(J37="tablet",J37="mobile")) -> FALSE | O37: =COUNTIF(refunds!$B$2:$B$15,A37)>0 -> FALSE | P37: =_xlfn.XLOOKUP(A37,refunds!$B$2:$B$15,refunds!$D$2:$D$15,0,0) -> 0 | Q37: =IF(OR(payments[[#This Row],[completed_at]]="",payments[[#This Row],[completed_at]]=0),"",TEXT(payments[[#This Row],[completed_at]],"yyyy-mm")) -> 2026-02
A38: 23 | B38: 91 | C38: 2 | D38: 46092.709 | E38: 46092.709 | F38: succeeded | G38: 9.99 | H38: 250 | I38: =_xlfn.XLOOKUP(B38,users!A:A,users!C:C) -> GB | J38: =_xlfn.XLOOKUP(B38,users!A:A,users!D:D) -> mobile | K38: =_xlfn.XLOOKUP(C38,coin_packages!A:A,coin_packages!B:B) -> Medium | L38: {=INDEX(coin_packages!$B$2:$B$5,MATCH(C38,coin_packages!$A$2:$A$5,0))} -> Medium | M38: =IF(F38="succeeded",G38,0) -> 9.99 | N38: =AND(F38="succeeded",I38="US",OR(J38="tablet",J38="mobile")) -> FALSE | O38: =COUNTIF(refunds!$B$2:$B$15,A38)>0 -> FALSE | P38: =_xlfn.XLOOKUP(A38,refunds!$B$2:$B$15,refunds!$D$2:$D$15,0,0) -> 0 | Q38: =IF(OR(payments[[#This Row],[completed_at]]="",payments[[#This Row],[completed_at]]=0),"",TEXT(payments[[#This Row],[completed_at]],"yyyy-mm")) -> 2026-03
A39: 22 | B39: 91 | C39: 3 | D39: 46089.66 | F39: failed | G39: 19.99 | H39: 0 | I39: =_xlfn.XLOOKUP(B39,users!A:A,users!C:C) -> GB | J39: =_xlfn.XLOOKUP(B39,users!A:A,users!D:D) -> mobile | K39: =_xlfn.XLOOKUP(C39,coin_packages!A:A,coin_packages!B:B) -> Large | L39: {=INDEX(coin_packages!$B$2:$B$5,MATCH(C39,coin_packages!$A$2:$A$5,0))} -> Large | M39: =IF(F39="succeeded",G39,0) -> 0 | N39: =AND(F39="succeeded",I39="US",OR(J39="tablet",J39="mobile")) -> FALSE | O39: =COUNTIF(refunds!$B$2:$B$15,A39)>0 -> FALSE | P39: =_xlfn.XLOOKUP(A39,refunds!$B$2:$B$15,refunds!$D$2:$D$15,0,0) -> 0 | Q39: =IF(OR(payments[[#This Row],[completed_at]]="",payments[[#This Row],[completed_at]]=0),"",TEXT(payments[[#This Row],[completed_at]],"yyyy-mm"))
A40: 24 | B40: 99 | C40: 2 | D40: 46154.703 | E40: 46154.703 | F40: succeeded | G40: 9.99 | H40: 250 | I40: =_xlfn.XLOOKUP(B40,users!A:A,users!C:C) -> DE | J40: =_xlfn.XLOOKUP(B40,users!A:A,users!D:D) -> tablet | K40: =_xlfn.XLOOKUP(C40,coin_packages!A:A,coin_packages!B:B) -> Medium | L40: {=INDEX(coin_packages!$B$2:$B$5,MATCH(C40,coin_packages!$A$2:$A$5,0))} -> Medium | M40: =IF(F40="succeeded",G40,0) -> 9.99 | N40: =AND(F40="succeeded",I40="US",OR(J40="tablet",J40="mobile")) -> FALSE | O40: =COUNTIF(refunds!$B$2:$B$15,A40)>0 -> FALSE | P40: =_xlfn.XLOOKUP(A40,refunds!$B$2:$B$15,refunds!$D$2:$D$15,0,0) -> 0 | Q40: =IF(OR(payments[[#This Row],[completed_at]]="",payments[[#This Row],[completed_at]]=0),"",TEXT(payments[[#This Row],[completed_at]],"yyyy-mm")) -> 2026-05
...

Sheet refunds
A1: refund_id | B1: payment_id | C1: refunded_at | D1: amount_usd | E1: coins_revoked | F1: reason | G1: user_id | H1: Month
A2: 1 | B2: 9 | C2: 46136.875 | D2: 9.99 | E2: 250 | F2: customer_request | G2: =_xlfn.XLOOKUP(B2,payments!$A$2:$A$203,payments!$B$2:$B$203) -> 49 | H2: =IF(OR(refunds[[#This Row],[refunded_at]]="",refunds[[#This Row],[refunded_at]]=0),"",TEXT(refunds[[#This Row],[refunded_at]],"yyyy-mm")) -> 2026-04
A3: 2 | B3: 63 | C3: 46183.144 | D3: 9.99 | E3: 250 | F3: accidental_purchase | G3: =_xlfn.XLOOKUP(B3,payments!$A$2:$A$203,payments!$B$2:$B$203) -> 214 | H3: =IF(OR(refunds[[#This Row],[refunded_at]]="",refunds[[#This Row],[refunded_at]]=0),"",TEXT(refunds[[#This Row],[refunded_at]],"yyyy-mm")) -> 2026-06
A4: 3 | B4: 75 | C4: 46142.882 | D4: 19.99 | E4: 600 | F4: customer_request | G4: =_xlfn.XLOOKUP(B4,payments!$A$2:$A$203,payments!$B$2:$B$203) -> 246 | H4: =IF(OR(refunds[[#This Row],[refunded_at]]="",refunds[[#This Row],[refunded_at]]=0),"",TEXT(refunds[[#This Row],[refunded_at]],"yyyy-mm")) -> 2026-04
A5: 4 | B5: 81 | C5: 46043.996 | D5: 19.99 | E5: 600 | F5: accidental_purchase | G5: =_xlfn.XLOOKUP(B5,payments!$A$2:$A$203,payments!$B$2:$B$203) -> 252 | H5: =IF(OR(refunds[[#This Row],[refunded_at]]="",refunds[[#This Row],[refunded_at]]=0),"",TEXT(refunds[[#This Row],[refunded_at]],"yyyy-mm")) -> 2026-01
A6: 5 | B6: 94 | C6: 46104.459 | D6: 19.99 | E6: 600 | F6: customer_request | G6: =_xlfn.XLOOKUP(B6,payments!$A$2:$A$203,payments!$B$2:$B$203) -> 299 | H6: =IF(OR(refunds[[#This Row],[refunded_at]]="",refunds[[#This Row],[refunded_at]]=0),"",TEXT(refunds[[#This Row],[refunded_at]],"yyyy-mm")) -> 2026-03
A7: 6 | B7: 95 | C7: 46108.757 | D7: 19.99 | E7: 600 | F7: accidental_purchase | G7: =_xlfn.XLOOKUP(B7,payments!$A$2:$A$203,payments!$B$2:$B$203) -> 299 | H7: =IF(OR(refunds[[#This Row],[refunded_at]]="",refunds[[#This Row],[refunded_at]]=0),"",TEXT(refunds[[#This Row],[refunded_at]],"yyyy-mm")) -> 2026-03
A8: 7 | B8: 101 | C8: 46140.336 | D8: 4.99 | E8: 100 | F8: customer_request | G8: =_xlfn.XLOOKUP(B8,payments!$A$2:$A$203,payments!$B$2:$B$203) -> 314 | H8: =IF(OR(refunds[[#This Row],[refunded_at]]="",refunds[[#This Row],[refunded_at]]=0),"",TEXT(refunds[[#This Row],[refunded_at]],"yyyy-mm")) -> 2026-04
A9: 8 | B9: 104 | C9: 46154.531 | D9: 19.99 | E9: 600 | F9: accidental_purchase | G9: =_xlfn.XLOOKUP(B9,payments!$A$2:$A$203,payments!$B$2:$B$203) -> 320 | H9: =IF(OR(refunds[[#This Row],[refunded_at]]="",refunds[[#This Row],[refunded_at]]=0),"",TEXT(refunds[[#This Row],[refunded_at]],"yyyy-mm")) -> 2026-05
A10: 9 | B10: 114 | C10: 46164.231 | D10: 19.99 | E10: 600 | F10: accidental_purchase | G10: =_xlfn.XLOOKUP(B10,payments!$A$2:$A$203,payments!$B$2:$B$203) -> 342 | H10: =IF(OR(refunds[[#This Row],[refunded_at]]="",refunds[[#This Row],[refunded_at]]=0),"",TEXT(refunds[[#This Row],[refunded_at]],"yyyy-mm")) -> 2026-05
A11: 10 | B11: 124 | C11: 46079.3 | D11: 9.99 | E11: 250 | F11: customer_request | G11: =_xlfn.XLOOKUP(B11,payments!$A$2:$A$203,payments!$B$2:$B$203) -> 369 | H11: =IF(OR(refunds[[#This Row],[refunded_at]]="",refunds[[#This Row],[refunded_at]]=0),"",TEXT(refunds[[#This Row],[refunded_at]],"yyyy-mm")) -> 2026-02
A12: 11 | B12: 126 | C12: 46154.778 | D12: 9.99 | E12: 250 | F12: customer_request | G12: =_xlfn.XLOOKUP(B12,payments!$A$2:$A$203,payments!$B$2:$B$203) -> 369 | H12: =IF(OR(refunds[[#This Row],[refunded_at]]="",refunds[[#This Row],[refunded_at]]=0),"",TEXT(refunds[[#This Row],[refunded_at]],"yyyy-mm")) -> 2026-05
A13: 12 | B13: 134 | C13: 46042.69 | D13: 19.99 | E13: 600 | F13: customer_request | G13: =_xlfn.XLOOKUP(B13,payments!$A$2:$A$203,payments!$B$2:$B$203) -> 384 | H13: =IF(OR(refunds[[#This Row],[refunded_at]]="",refunds[[#This Row],[refunded_at]]=0),"",TEXT(refunds[[#This Row],[refunded_at]],"yyyy-mm")) -> 2026-01
... A15: 14 | B15: 165 | C15: 46199.825 | D15: 19.99 | E15: 600 | F15: customer_request | G15: =_xlfn.XLOOKUP(B15,payments!$A$2:$A$203,payments!$B$2:$B$203) -> 450 | H15: =IF(OR(refunds[[#This Row],[refunded_at]]="",refunds[[#This Row],[refunded_at]]=0),"",TEXT(refunds[[#This Row],[refunded_at]],"yyyy-mm")) -> 2026-06

Sheet coin_packages
A1: package_id | B1: package_name | C1: coins | D1: list_price_usd
A2: 1 | B2: Small | C2: 100 | D2: 4.99
A3: 2 | B3: Medium | C3: 250 | D3: 9.99
A4: 3 | B4: Large | C4: 600 | D4: 19.99
A5: 4 | B5: Unused premium | C5: 1500 | D5: 44.99

Sheet campaigns
A1: campaign_id | B1: campaign_name | C1: channel | D1: started_at | E1: ended_at | F1: spend_usd
A2: 1 | B2: Campaign_01 | C2: Meta | D2: 46023 | E2: 46204 | F2: 1086
A3: 2 | B3: Campaign_02 | C3: TikTok | D3: 46023 | E3: 46204 | F3: 961
A4: 3 | B4: Campaign_03 | C4: Google | D4: 46023 | E4: 46204 | F4: 1373
A5: 4 | B5: Campaign_04 | C5: Influencer | D5: 46023 | E5: 46204 | F5: 1042
A6: 5 | B6: Campaign_05 | C6: Meta | D6: 46023 | E6: 46204 | F6: 377
A7: 6 | B7: Campaign_06 | C7: TikTok | D7: 46023 | E7: 46204 | F7: 1795
A8: 7 | B8: Campaign_07 | C8: Google | D8: 46023 | E8: 46204 | F8: 719
A9: 8 | B9: Campaign_08 | C9: Influencer | D9: 46023 | E9: 46204 | F9: 1545

Sheet Summary
A1: Кількість успішних платежів | B1: Загальна сума успішних платежів | C1: Середній успішний платіж | D1: Медіанний успішний платіж | E1: Курс USD/UAH
A2: =COUNTIF(payments!F:F,"succeeded") -> 163 | B2: =SUMIF(payments!F:F,"succeeded",payments!G:G) -> 1927.37 | C2: =B2/A2 -> 11.824356 | D2: {=MEDIAN(_xlfn._xlws.FILTER(payments!G2:G203,payments!F2:F203="succeeded"))} -> 9.99 | E2: 40
A3: =A2*$E$2 -> 6520 | B3: =B2*$E$2 -> 77094.8 | C3: =C2*$E$2 -> 472.97423 | D3: =D2*$E$2 -> 399.6
A4: =ROUND(A3,2) -> 6520 | B4: =ROUND(B3,2) -> 77094.8 | C4: =ROUND(C3,2) -> 472.97 | D4: =ROUND(D3,2) -> 399.6
